<?xml version="1.0" ?>
<robot name="august" xmlns:xacro="http://www.ros.org/wiki/xacro">

<xacro:include filename="$(find august_description)/urdf/materials.xacro" />
<xacro:include filename="$(find august_description)/urdf/august.trans" />
<xacro:include filename="$(find august_description)/urdf/august.gazebo" />
<link name="base_link">
  <inertial>
    <origin xyz="0.0367840763564357 0.0188810759037174 0.006751541549144135" rpy="0 0 0"/>
    <mass value="0.2085309750042539"/>
    <inertia ixx="0.000917" iyy="0.000923" izz="0.001817" ixy="2e-05" iyz="-9e-06" ixz="-0.0"/>
  </inertial>
  <visual>
    <origin xyz="0 0 0" rpy="0 0 0"/>
    <geometry>
      <mesh filename="package://august_description/meshes/base_link.stl" scale="0.001 0.001 0.001"/>
    </geometry>
    <material name="silver"/>
  </visual>
  <collision>
    <origin xyz="0 0 0" rpy="0 0 0"/>
    <geometry>
      <mesh filename="package://august_description/meshes/base_link.stl" scale="0.001 0.001 0.001"/>
    </geometry>
  </collision>
</link>

<link name="a_1_1">
  <inertial>
    <origin xyz="2.526086163301411e-07 1.7914087944992385e-07 -0.005529437283473382" rpy="0 0 0"/>
    <mass value="0.08002386365525722"/>
    <inertia ixx="0.000261" iyy="5e-06" izz="0.000266" ixy="-2.8e-05" iyz="0.0" ixz="0.0"/>
  </inertial>
  <visual>
    <origin xyz="-0.154704 0.082227 -0.032573" rpy="0 0 0"/>
    <geometry>
      <mesh filename="package://august_description/meshes/a_1_1.stl" scale="0.001 0.001 0.001"/>
    </geometry>
    <material name="silver"/>
  </visual>
  <collision>
    <origin xyz="-0.154704 0.082227 -0.032573" rpy="0 0 0"/>
    <geometry>
      <mesh filename="package://august_description/meshes/a_1_1.stl" scale="0.001 0.001 0.001"/>
    </geometry>
  </collision>
</link>

<link name="b_2_1">
  <inertial>
    <origin xyz="-2.089503201019305e-08 3.1764028338154837e-07 -0.005530056412288993" rpy="0 0 0"/>
    <mass value="0.08002386365525736"/>
    <inertia ixx="0.000258" iyy="8e-06" izz="0.000266" ixy="-4e-05" iyz="0.0" ixz="0.0"/>
  </inertial>
  <visual>
    <origin xyz="-0.154898 -0.114909 -0.037559" rpy="0 0 0"/>
    <geometry>
      <mesh filename="package://august_description/meshes/b`_1_1.stl" scale="0.001 0.001 0.001"/>
    </geometry>
    <material name="silver"/>
  </visual>
  <collision>
    <origin xyz="-0.154898 -0.114909 -0.037559" rpy="0 0 0"/>
    <geometry>
      <mesh filename="package://august_description/meshes/b`_1_1.stl" scale="0.001 0.001 0.001"/>
    </geometry>
  </collision>
</link>

<link name="b_1_1">
  <inertial>
    <origin xyz="4.860236744730351e-07 3.263587135537982e-07 -0.005530056412288542" rpy="0 0 0"/>
    <mass value="0.08002386365525739"/>
    <inertia ixx="0.000263" iyy="4e-06" izz="0.000266" ixy="2.2e-05" iyz="-0.0" ixz="0.0"/>
  </inertial>
  <visual>
    <origin xyz="0.084483 -0.117659 -0.037559" rpy="0 0 0"/>
    <geometry>
      <mesh filename="package://august_description/meshes/b_1_1.stl" scale="0.001 0.001 0.001"/>
    </geometry>
    <material name="silver"/>
  </visual>
  <collision>
    <origin xyz="0.084483 -0.117659 -0.037559" rpy="0 0 0"/>
    <geometry>
      <mesh filename="package://august_description/meshes/b_1_1.stl" scale="0.001 0.001 0.001"/>
    </geometry>
  </collision>
</link>

<link name="a_2_1">
  <inertial>
    <origin xyz="-2.735505639922531e-07 -1.4786139410083443e-07 -0.005530056891346981" rpy="0 0 0"/>
    <mass value="0.08002386365525742"/>
    <inertia ixx="0.000263" iyy="4e-06" izz="0.000266" ixy="2.2e-05" iyz="-0.0" ixz="0.0"/>
  </inertial>
  <visual>
    <origin xyz="0.082471 0.081741 -0.032559" rpy="0 0 0"/>
    <geometry>
      <mesh filename="package://august_description/meshes/a`_1_1.stl" scale="0.001 0.001 0.001"/>
    </geometry>
    <material name="silver"/>
  </visual>
  <collision>
    <origin xyz="0.082471 0.081741 -0.032559" rpy="0 0 0"/>
    <geometry>
      <mesh filename="package://august_description/meshes/a`_1_1.stl" scale="0.001 0.001 0.001"/>
    </geometry>
  </collision>
</link>

<joint name="Revolute 55" type="continuous">
  <origin xyz="0.154704 -0.082227 0.032573" rpy="0 0 0"/>
  <parent link="base_link"/>
  <child link="a_1_1"/>
  <axis xyz="-0.0 -0.0 -1.0"/>
  <limit upper="6.283185" lower="0.0" effort="0" velocity="0"/>
</joint>

<joint name="Revolute 56" type="continuous">
  <origin xyz="0.154898 0.114909 0.037559" rpy="0 0 0"/>
  <parent link="base_link"/>
  <child link="b_2_1"/>
  <axis xyz="0.0 -0.0 -1.0"/>
  <limit upper="6.283185" lower="0.0" effort="0" velocity="0"/>
</joint>

<joint name="Revolute 57" type="revolute">
  <origin xyz="-0.084483 0.117659 0.037559" rpy="0 0 0"/>
  <parent link="base_link"/>
  <child link="b_1_1"/>
  <axis xyz="0.0 0.0 -1.0"/>
  <limit upper="6.283185" lower="0.0" effort="0" velocity="0"/>
</joint>

<joint name="Revolute 58" type="continuous">
  <origin xyz="-0.082471 -0.081741 0.032559" rpy="0 0 0"/>
  <parent link="base_link"/>
  <child link="a_2_1"/>
  <axis xyz="-0.0 0.0 -1.0"/>
  <limit upper="6.283185" lower="0.0" effort="0" velocity="0"/>
</joint>

</robot>
